INFO:TeleBot:Started polling.
ERROR:TeleBot:ConnectionError occurred, args=(ProtocolError('Connection aborted.', ConnectionResetError(10054, 'An existing connection was forcibly closed by the remote host', None, 10054, None)),)
Traceback (most recent call last):
  File "C:\Users\THANHHIEU\AppData\Local\Programs\Python\Python36-32\lib\site-packages\requests\packages\urllib3\connectionpool.py", line 600, in urlopen
    chunked=chunked)
  File "C:\Users\THANHHIEU\AppData\Local\Programs\Python\Python36-32\lib\site-packages\requests\packages\urllib3\connectionpool.py", line 386, in _make_request
    six.raise_from(e, None)
  File "<string>", line 2, in raise_from
  File "C:\Users\THANHHIEU\AppData\Local\Programs\Python\Python36-32\lib\site-packages\requests\packages\urllib3\connectionpool.py", line 382, in _make_request
    httplib_response = conn.getresponse()
  File "C:\Users\THANHHIEU\AppData\Local\Programs\Python\Python36-32\lib\http\client.py", line 1331, in getresponse
    response.begin()
  File "C:\Users\THANHHIEU\AppData\Local\Programs\Python\Python36-32\lib\http\client.py", line 297, in begin
    version, status, reason = self._read_status()
  File "C:\Users\THANHHIEU\AppData\Local\Programs\Python\Python36-32\lib\http\client.py", line 258, in _read_status
    line = str(self.fp.readline(_MAXLINE + 1), "iso-8859-1")
  File "C:\Users\THANHHIEU\AppData\Local\Programs\Python\Python36-32\lib\socket.py", line 586, in readinto
    return self._sock.recv_into(b)
  File "C:\Users\THANHHIEU\AppData\Local\Programs\Python\Python36-32\lib\ssl.py", line 1009, in recv_into
    return self.read(nbytes, buffer)
  File "C:\Users\THANHHIEU\AppData\Local\Programs\Python\Python36-32\lib\ssl.py", line 871, in read
    return self._sslobj.read(len, buffer)
  File "C:\Users\THANHHIEU\AppData\Local\Programs\Python\Python36-32\lib\ssl.py", line 631, in read
    v = self._sslobj.read(len, buffer)
ConnectionResetError: [WinError 10054] An existing connection was forcibly closed by the remote host

During handling of the above exception, another exception occurred:

Traceback (most recent call last):
  File "C:\Users\THANHHIEU\AppData\Local\Programs\Python\Python36-32\lib\site-packages\requests\adapters.py", line 423, in send
    timeout=timeout
  File "C:\Users\THANHHIEU\AppData\Local\Programs\Python\Python36-32\lib\site-packages\requests\packages\urllib3\connectionpool.py", line 649, in urlopen
    _stacktrace=sys.exc_info()[2])
  File "C:\Users\THANHHIEU\AppData\Local\Programs\Python\Python36-32\lib\site-packages\requests\packages\urllib3\util\retry.py", line 347, in increment
    raise six.reraise(type(error), error, _stacktrace)
  File "C:\Users\THANHHIEU\AppData\Local\Programs\Python\Python36-32\lib\site-packages\requests\packages\urllib3\packages\six.py", line 685, in reraise
    raise value.with_traceback(tb)
  File "C:\Users\THANHHIEU\AppData\Local\Programs\Python\Python36-32\lib\site-packages\requests\packages\urllib3\connectionpool.py", line 600, in urlopen
    chunked=chunked)
  File "C:\Users\THANHHIEU\AppData\Local\Programs\Python\Python36-32\lib\site-packages\requests\packages\urllib3\connectionpool.py", line 386, in _make_request
    six.raise_from(e, None)
  File "<string>", line 2, in raise_from
  File "C:\Users\THANHHIEU\AppData\Local\Programs\Python\Python36-32\lib\site-packages\requests\packages\urllib3\connectionpool.py", line 382, in _make_request
    httplib_response = conn.getresponse()
  File "C:\Users\THANHHIEU\AppData\Local\Programs\Python\Python36-32\lib\http\client.py", line 1331, in getresponse
    response.begin()
  File "C:\Users\THANHHIEU\AppData\Local\Programs\Python\Python36-32\lib\http\client.py", line 297, in begin
    version, status, reason = self._read_status()
  File "C:\Users\THANHHIEU\AppData\Local\Programs\Python\Python36-32\lib\http\client.py", line 258, in _read_status
    line = str(self.fp.readline(_MAXLINE + 1), "iso-8859-1")
  File "C:\Users\THANHHIEU\AppData\Local\Programs\Python\Python36-32\lib\socket.py", line 586, in readinto
    return self._sock.recv_into(b)
  File "C:\Users\THANHHIEU\AppData\Local\Programs\Python\Python36-32\lib\ssl.py", line 1009, in recv_into
    return self.read(nbytes, buffer)
  File "C:\Users\THANHHIEU\AppData\Local\Programs\Python\Python36-32\lib\ssl.py", line 871, in read
    return self._sslobj.read(len, buffer)
  File "C:\Users\THANHHIEU\AppData\Local\Programs\Python\Python36-32\lib\ssl.py", line 631, in read
    v = self._sslobj.read(len, buffer)
requests.packages.urllib3.exceptions.ProtocolError: ('Connection aborted.', ConnectionResetError(10054, 'An existing connection was forcibly closed by the remote host', None, 10054, None))

During handling of the above exception, another exception occurred:

Traceback (most recent call last):
  File "C:\Users\THANHHIEU\AppData\Local\Programs\Python\Python36-32\lib\site-packages\telebot\util.py", line 58, in run
    task(*args, **kwargs)
  File "C:\Users\THANHHIEU\AppData\Local\Programs\Python\Python36-32\lib\site-packages\telebot\__init__.py", line 159, in __retrieve_updates
    updates = self.get_updates(offset=(self.last_update_id + 1), timeout=timeout)
  File "C:\Users\THANHHIEU\AppData\Local\Programs\Python\Python36-32\lib\site-packages\telebot\__init__.py", line 129, in get_updates
    json_updates = apihelper.get_updates(self.token, offset, limit, timeout, allowed_updates)
  File "C:\Users\THANHHIEU\AppData\Local\Programs\Python\Python36-32\lib\site-packages\telebot\apihelper.py", line 175, in get_updates
    return _make_request(token, method_url, params=payload)
  File "C:\Users\THANHHIEU\AppData\Local\Programs\Python\Python36-32\lib\site-packages\telebot\apihelper.py", line 54, in _make_request
    timeout=(connect_timeout, read_timeout), proxies=proxy)
  File "C:\Users\THANHHIEU\AppData\Local\Programs\Python\Python36-32\lib\site-packages\requests\sessions.py", line 488, in request
    resp = self.send(prep, **send_kwargs)
  File "C:\Users\THANHHIEU\AppData\Local\Programs\Python\Python36-32\lib\site-packages\requests\sessions.py", line 609, in send
    r = adapter.send(request, **kwargs)
  File "C:\Users\THANHHIEU\AppData\Local\Programs\Python\Python36-32\lib\site-packages\requests\adapters.py", line 473, in send
    raise ConnectionError(err, request=request)
requests.exceptions.ConnectionError: ('Connection aborted.', ConnectionResetError(10054, 'An existing connection was forcibly closed by the remote host', None, 10054, None))

