INFO:TeleBot:Started polling.
ERROR:TeleBot:NameError occurred, args=("name 'track_message' is not defined",)
Traceback (most recent call last):
  File "C:\Users\THANHHIEU\AppData\Local\Programs\Python\Python36-32\lib\site-packages\telebot\util.py", line 58, in run
    task(*args, **kwargs)
  File "main.py", line 311, in search
    track_message(msg.from_user.id, msg, 'receive_message')
NameError: name 'track_message' is not defined

